2016-09-17 11:28:43,072 - telegram.ext.dispatcher - ERROR - An uncaught error was raised while processing the update
Traceback (most recent call last):
  File "D:\Python27\lib\site-packages\telegram\ext\dispatcher.py", line 203, in process_update
    handler.handle_update(update, self)
  File "D:\Python27\lib\site-packages\telegram\ext\conversationhandler.py", line 210, in handle_update
    new_state = self.current_handler.handle_update(update, dispatcher)
  File "D:\Python27\lib\site-packages\telegram\ext\regexhandler.py", line 92, in handle_update
    return self.callback(dispatcher.bot, update, **optional_args)
  File "D:/Yoni/Programming/Python/TheOctobot/conv-bot.py", line 187, in activate_timer
    elif time:
NameError: global name 'time' is not defined
2016-09-17 11:31:04,509 - JobQueue - ERROR - An uncaught error was raised while executing job reminder_alarm
Traceback (most recent call last):
  File "D:\Python27\lib\site-packages\telegram\ext\jobqueue.py", line 128, in tick
    job.run(self.bot)
  File "D:\Python27\lib\site-packages\telegram\ext\jobqueue.py", line 233, in run
    self.callback(bot, self)
  File "D:/Yoni/Programming/Python/TheOctobot/conv-bot.py", line 208, in reminder_alarm
    bot.sendMessage(job.context.chat_id,
AttributeError: 'dict' object has no attribute 'chat_id'
2016-09-17 11:42:27,657 - telegram.ext.dispatcher - ERROR - An uncaught error was raised while processing the update
Traceback (most recent call last):
  File "D:\Python27\lib\site-packages\telegram\ext\dispatcher.py", line 203, in process_update
    handler.handle_update(update, self)
  File "D:\Python27\lib\site-packages\telegram\ext\conversationhandler.py", line 210, in handle_update
    new_state = self.current_handler.handle_update(update, dispatcher)
  File "D:\Python27\lib\site-packages\telegram\ext\regexhandler.py", line 92, in handle_update
    return self.callback(dispatcher.bot, update, **optional_args)
  File "D:/Yoni/Programming/Python/TheOctobot/conv-bot.py", line 138, in choose_time
    date = date.replace(hour=time.hour, minutes=time.minute)
TypeError: 'minutes' is an invalid keyword argument for this function
2016-09-17 11:44:51,323 - telegram.ext.dispatcher - ERROR - An uncaught error was raised while processing the update
Traceback (most recent call last):
  File "D:\Python27\lib\site-packages\telegram\ext\dispatcher.py", line 203, in process_update
    handler.handle_update(update, self)
  File "D:\Python27\lib\site-packages\telegram\ext\conversationhandler.py", line 210, in handle_update
    new_state = self.current_handler.handle_update(update, dispatcher)
  File "D:\Python27\lib\site-packages\telegram\ext\regexhandler.py", line 92, in handle_update
    return self.callback(dispatcher.bot, update, **optional_args)
  File "D:/Yoni/Programming/Python/TheOctobot/conv-bot.py", line 138, in choose_time
    date = date.replace(hour=time.hour, minute=time.minute, second=0, milisecond=0)
TypeError: 'milisecond' is an invalid keyword argument for this function
2016-09-17 20:34:30,799 - telegram.ext.dispatcher - ERROR - An uncaught error was raised while processing the update
Traceback (most recent call last):
  File "D:\Python27\lib\site-packages\telegram\ext\dispatcher.py", line 203, in process_update
    handler.handle_update(update, self)
  File "D:\Python27\lib\site-packages\telegram\ext\conversationhandler.py", line 210, in handle_update
    new_state = self.current_handler.handle_update(update, dispatcher)
  File "D:\Python27\lib\site-packages\telegram\ext\messagehandler.py", line 139, in handle_update
    return self.callback(dispatcher.bot, update, **optional_args)
  File "D:/Yoni/Programming/Python/TheOctobot/conv-bot.py", line 125, in choose_day
    date = datetime.strptime(update.message.text, '%d/%m/%y') # TODO: can i just add the time here instead of creating another conversation choose_time
  File "D:\Python27\lib\_strptime.py", line 332, in _strptime
    (data_string, format))
ValueError: time data 'Another date' does not match format '%d/%m/%y'
2016-09-17 20:34:52,915 - telegram.ext.dispatcher - ERROR - An uncaught error was raised while processing the update
Traceback (most recent call last):
  File "D:\Python27\lib\site-packages\telegram\ext\dispatcher.py", line 203, in process_update
    handler.handle_update(update, self)
  File "D:\Python27\lib\site-packages\telegram\ext\conversationhandler.py", line 210, in handle_update
    new_state = self.current_handler.handle_update(update, dispatcher)
  File "D:\Python27\lib\site-packages\telegram\ext\messagehandler.py", line 139, in handle_update
    return self.callback(dispatcher.bot, update, **optional_args)
  File "D:/Yoni/Programming/Python/TheOctobot/conv-bot.py", line 125, in choose_day
    date = datetime.strptime(update.message.text, '%d/%m/%y') # TODO: can i just add the time here instead of creating another conversation choose_time
  File "D:\Python27\lib\_strptime.py", line 335, in _strptime
    data_string[found.end():])
ValueError: unconverted data remains: 16
2016-09-17 20:36:03,405 - telegram.ext.dispatcher - ERROR - An uncaught error was raised while processing the update
Traceback (most recent call last):
  File "D:\Python27\lib\site-packages\telegram\ext\dispatcher.py", line 203, in process_update
    handler.handle_update(update, self)
  File "D:\Python27\lib\site-packages\telegram\ext\conversationhandler.py", line 210, in handle_update
    new_state = self.current_handler.handle_update(update, dispatcher)
  File "D:\Python27\lib\site-packages\telegram\ext\messagehandler.py", line 139, in handle_update
    return self.callback(dispatcher.bot, update, **optional_args)
  File "D:/Yoni/Programming/Python/TheOctobot/conv-bot.py", line 125, in choose_day
    date = datetime.strptime(update.message.text, '%d/%m/%y') # TODO: can i just add the time here instead of creating another conversation choose_time
  File "D:\Python27\lib\_strptime.py", line 332, in _strptime
    (data_string, format))
ValueError: time data 'Another date' does not match format '%d/%m/%y'
2016-09-17 21:36:50,545 - telegram.ext.dispatcher - ERROR - An uncaught error was raised while processing the update
Traceback (most recent call last):
  File "D:\Python27\lib\site-packages\telegram\ext\dispatcher.py", line 203, in process_update
    handler.handle_update(update, self)
  File "D:\Python27\lib\site-packages\telegram\ext\conversationhandler.py", line 210, in handle_update
    new_state = self.current_handler.handle_update(update, dispatcher)
  File "D:\Python27\lib\site-packages\telegram\ext\regexhandler.py", line 92, in handle_update
    return self.callback(dispatcher.bot, update, **optional_args)
  File "D:/Yoni/Programming/Python/TheOctobot/conv-bot.py", line 179, in set_timer
    'Details:\n' + current_reminder.to_string(),
  File "D:\Yoni\Programming\Python\TheOctobot\reminder.py", line 25, in to_string
    (self.reminder_timer.seconds % 3600) % 60)
TypeError: format() takes at most 2 arguments (4 given)
2016-09-17 21:52:45,655 - telegram.ext.dispatcher - ERROR - An uncaught error was raised while processing the update
Traceback (most recent call last):
  File "D:\Python27\lib\site-packages\telegram\ext\dispatcher.py", line 203, in process_update
    handler.handle_update(update, self)
  File "D:\Python27\lib\site-packages\telegram\ext\conversationhandler.py", line 210, in handle_update
    new_state = self.current_handler.handle_update(update, dispatcher)
  File "D:\Python27\lib\site-packages\telegram\ext\regexhandler.py", line 92, in handle_update
    return self.callback(dispatcher.bot, update, **optional_args)
  File "D:/Yoni/Programming/Python/TheOctobot/conv-bot.py", line 179, in set_timer
    'Details:\n' + current_reminder.to_string(),
  File "D:\Yoni\Programming\Python\TheOctobot\reminder.py", line 25, in to_string
    (self.reminder_timer.seconds % 3600) % 60 + ' seconds\n',
TypeError: cannot concatenate 'str' and 'int' objects
2016-09-17 22:13:26,140 - telegram.ext.dispatcher - ERROR - An uncaught error was raised while processing the update
Traceback (most recent call last):
  File "D:\Python27\lib\site-packages\telegram\ext\dispatcher.py", line 203, in process_update
    handler.handle_update(update, self)
  File "D:\Python27\lib\site-packages\telegram\ext\conversationhandler.py", line 210, in handle_update
    new_state = self.current_handler.handle_update(update, dispatcher)
  File "D:\Python27\lib\site-packages\telegram\ext\regexhandler.py", line 92, in handle_update
    return self.callback(dispatcher.bot, update, **optional_args)
  File "D:/Yoni/Programming/Python/TheOctobot/conv-bot.py", line 179, in set_timer
    'Details:\n' + current_reminder.to_string(),
  File "D:\Yoni\Programming\Python\TheOctobot\reminder.py", line 25, in to_string
    str((self.reminder_timer.seconds % 3600) % 60) + ' seconds\n',
TypeError: coercing to Unicode: need string or buffer, tuple found
